Failure # 1 (occurred at 2023-10-20_17-18-52)
[36mray::ImplicitFunc.train()[39m (pid=2498436, ip=10.125.1.185, actor_id=95d87577120c6f846fcb08e201000000, repr=_objective)
           ^^^^^^^^^^^^^^^^^^^^^^^^^^^^^^^^^^^^
           ^^^^^^^^^^^^^^^^^^^^^^^^^^^^^^^
  File "/scratch/taw2/conda_envs/biosift_env/lib/python3.11/site-packages/ray/tune/trainable/trainable.py", line 375, in train
    raise skipped from exception_cause(skipped)
  File "/scratch/taw2/conda_envs/biosift_env/lib/python3.11/site-packages/ray/tune/trainable/function_trainable.py", line 349, in entrypoint
    return self._trainable_func(
           ^^^^^^^^^^^^^^^^^^^^^
           ^^^^^^^^^^^^^^^^^^^^^^^^^^^^^^^
  File "/scratch/taw2/conda_envs/biosift_env/lib/python3.11/site-packages/ray/tune/trainable/function_trainable.py", line 666, in _trainable_func
    output = fn()
             ^^^^
  File "/scratch/taw2/conda_envs/biosift_env/lib/python3.11/site-packages/transformers/integrations/integration_utils.py", line 354, in dynamic_modules_import_trainable
    return trainable(*args, **kwargs)
           ^^^^^^^^^^^^^^^^^^^^^^^^^^
  File "/scratch/taw2/conda_envs/biosift_env/lib/python3.11/site-packages/ray/tune/trainable/util.py", line 324, in inner
    return trainable(config, **fn_kwargs)
           ^^^^^^^^^^^^^^^^^^^^^^^^^^^^^^
  File "/scratch/taw2/conda_envs/biosift_env/lib/python3.11/site-packages/transformers/integrations/integration_utils.py", line 255, in _objective
    local_trainer.train(resume_from_checkpoint=checkpoint, trial=trial)
  File "/scratch/taw2/conda_envs/biosift_env/lib/python3.11/site-packages/transformers/trainer.py", line 1591, in train
    return inner_training_loop(
           ^^^^^^^^^^^^^^^^^^^^
  File "/scratch/taw2/conda_envs/biosift_env/lib/python3.11/site-packages/transformers/trainer.py", line 1999, in _inner_training_loop
    self._maybe_log_save_evaluate(tr_loss, model, trial, epoch, ignore_keys_for_eval)
  File "/scratch/taw2/conda_envs/biosift_env/lib/python3.11/site-packages/transformers/trainer.py", line 2339, in _maybe_log_save_evaluate
    self._save_checkpoint(model, trial, metrics=metrics)
  File "/scratch/taw2/conda_envs/biosift_env/lib/python3.11/site-packages/transformers/trainer.py", line 2396, in _save_checkpoint
    self.save_model(output_dir, _internal_call=True)
  File "/scratch/taw2/conda_envs/biosift_env/lib/python3.11/site-packages/transformers/trainer.py", line 2901, in save_model
    self._save(output_dir)
  File "/scratch/taw2/conda_envs/biosift_env/lib/python3.11/site-packages/transformers/trainer.py", line 2938, in _save
    os.makedirs(output_dir, exist_ok=True)
  File "<frozen os>", line 215, in makedirs
  File "<frozen os>", line 225, in makedirs
PermissionError: [Errno 13] Permission denied: '/run-b41fc_00009'
